2025-03-16 16:39:16,097 : INFO : Start of Prediction
2025-03-16 16:39:16,098 : INFO : run_id:2025-03-16_163916_628772891
2025-03-16 16:39:16,098 : INFO : Start of Preprocessing...
2025-03-16 16:39:16,098 : INFO : Start of feature encoding...
2025-03-16 16:39:16,101 : INFO : End of feature encoding...
2025-03-16 16:39:16,103 : INFO : Start of Droping Columns...
2025-03-16 16:39:16,105 : INFO : End of Droping Columns...
2025-03-16 16:39:16,106 : INFO : Start of finding missing values...
2025-03-16 16:39:16,107 : INFO : End of finding missing values...
2025-03-16 16:39:16,114 : INFO : Start of building final predictset...
2025-03-16 16:39:16,122 : INFO : End of building final predictset...
2025-03-16 16:39:16,122 : INFO : End of Preprocessing...
2025-03-16 16:39:16,123 : INFO : Start of Load Model
2025-03-16 16:39:16,123 : INFO : Model File KMeans loaded
2025-03-16 16:39:16,124 : INFO : End of Load Model
2025-03-16 16:39:16,131 : INFO : clusters loop started
2025-03-16 16:39:16,133 : INFO : Start of finding correct model
2025-03-16 16:39:16,134 : INFO : Exception raised while finding correct model'FileOperation' object has no attribute 'model_name'
2025-03-16 16:39:16,134 : ERROR : Unsuccessful End of Prediction
Traceback (most recent call last):
  File "C:\Users\KIIT\PycharmProjects\PythonProject\apps\core\file_operation.py", line 113, in correct_model
    self.model_name=self.model_name.split('.')[0]
                    ^^^^^^^^^^^^^^^
AttributeError: 'FileOperation' object has no attribute 'model_name'

During handling of the above exception, another exception occurred:

Traceback (most recent call last):
  File "C:\Users\KIIT\PycharmProjects\PythonProject\apps\prediction\predict_model.py", line 110, in single_predict_from_model
    model_name = self.fileOperation.correct_model(i)
                 ^^^^^^^^^^^^^^^^^^^^^^^^^^^^^^^^^^^
  File "C:\Users\KIIT\PycharmProjects\PythonProject\apps\core\file_operation.py", line 118, in correct_model
    raise Exception()
Exception
